Workbook
Name PORTAFOGLIO_VENDITECOD: '[1]PORTAFOGLIO VEN §'!$A:$A

Sheet CRITICITA
A3: Etichette di riga
A4: -18° SAS
A5: BARATTI & MILANO SRL
A6: C.D.T. TOMARCHIO SRL
A7: COMPRITAL SPA
A8: DISARONNO INGREDIENTS S.P.A.
A9: ESKIGEL S.R.L.
A10: FABBRI 1905 SPA
A11: FASSI ISTITUTO BIOFARMACEUTICO SPA
A12: FRANCIACORTA CREME S.P.A.
A13: FRONERI ICE CREAM DEUTSCHLAND GMBH
A14: GLACES DES ALPES
... A33: Totale complessivo

Sheet Vettori
A1: Desc. vett. | B1: (più elementi)
A3: _Qta/kg da ev. | B3: _
A4: Etichette di riga | B4: 4 | C4: 8
A5: -18° SAS | C5: 2400
A6: BARATTI & MILANO SRL | C6: 4072
A7: C.D.T. TOMARCHIO SRL | C7: 150
A8: COMPRITAL SPA | C8: 800.7
A9: DISARONNO INGREDIENTS S.P.A. | C9: 7980
A10: ESKIGEL S.R.L. | C10: 3140
A11: FABBRI 1905 SPA | C11: 500.5
A12: FASSI ISTITUTO BIOFARMACEUTICO SPA | C12: 50
A13: FRANCIACORTA CREME S.P.A. | C13: 5000
A14: FRONERI ICE CREAM DEUTSCHLAND GMBH | C14: 6000
A15: GLACES DES ALPES | C15: 2.5
A16: LINDT & SPRÜNGLI S.p.A. | C16: 275
... A18: POLE SUD | C18: 1640
A19: PRE GEL SPA | B19: 1000 | C19: 100
A20: SAMMONTANA SPA Società Benefit | C20: 45984
A21: SIGEL GELATI S.R.L. | C21: 1280
A22: UNIGRA S.p.A | C22: 12401
A23: UNILEVER EUROPE B.V. | C23: 1280
A24: ELAH DUFOUR S.P.A. | C24: 6400
A25: LA SUISSA S.R.L. | C25: 5440.5
A26: MENZ&GASSER SPA | B26: 11441
A27: HANSENS FLODEIS | C27: 400
A28: GLACES DE BOURBON | C28: 500
A29: SN SOPROGLACES | C29: 2500
A30: NUTKAO S.R.L. | C30: 20000
A31: S.I.P.A. SPA | C31: 3380
A32: GOLOSI DI SALUTE SRL | C32: 2500

Sheet piano consegne
A3: Qta/kg da ev | B3: Etichette di colonna
A4: Etichette di riga | B4: 46037 | C4: 45996 | D4: 45992 | E4: 45971 | F4: Totale complessivo
A5: -18° SAS | B5: 1200 | F5: 1200
A6: LA SUISSA S.R.L. | C6: 2577.5 | F6: 2577.5
A7: GLACES DE BOURBON | D7: 500 | F7: 500
A8: AUSTRALIANSIAN FOOD GROUP TRADING AS ICE PETERS ICE CREAM | E8: 160 | F8: 160
A9: Totale complessivo | B9: 1200 | C9: 2577.5 | D9: 500 | E9: 160 | F9: 4437.5

Sheet appmerce_db
A1: Sel. | B1: Progr. | C1: Nr. ord. | D1: Ser. | E1: Data ordine | F1: Cod. | G1: Ragione sociale | H1: Articolo | I1: Cod. Cliente | J1: Descrizione art. cliente | K1: Qta/kg OV | L1: Qta/kg evasa | M1: Qta/kg da ev. | N1: Data sped. utile | O1: Data cons. rich. | P1: Desc. vett. | Q1: T-MIN | R1: T-MAX | S1: CONF | T1: Stato ordine | U1: Desc. Porto | V1: Desc Tipo Sp | W1: Descrizione | X1: Citta' | Y1: Gruppo | Z1: Descrizione famiglia | AA1: Sottofamigli | AB1: Descrizione sottofam | AC1: Famiglia | AD1: Gruppo | AE1: Desc gr/sgru | AF1: TIP.PROD. | AG1: Des.inf.stat | AH1: Codice vettore | AI1: Dt. Scad. | AJ1: Num Vs Ord | AK1: Data scadenza Contratto | AL1: Estero | AM1: CAP | AN1: giorno ritiro 1 | AO1: giorno ritiro 2 | AP1: resa | AQ1: Num DOC | AR1: provenienza | AS1: P/C | AT1: tot Pallet | AU1: giorno | AV1: No settimana | AW1: Check Data sped. utile | AX1: Check Data cons. rich. | AY1: Check Desc Tipo Sp | AZ1: Check Citta' | BA1: Check su data presa vettore | BB1: CHK GEN
A2: S | B2: 1 | C2: 557 | D2: 800 | E2: 45964 | F2: 58 | G2: ELAH DUFOUR S.P.A. | H2: MSGTT3436/G21 | I2: 21906/ G21 | J2: MANDORLE SGUSCIATE TOSTATE CAL. 34/36 QUAL. TUONO | K2: 6400 | M2: 6400 | O2: 45991 | P2: TRASPORTI RECUPERO SRL | Q2: 8 | R2: 10 | S2: G21 | T2: Non evaso | U2: DDP | V2: VETTORE | W2: ELAH DUFOUR S.P.A. | X2: 15067 NOVI LIGURE (AL) | Y2: 5 | Z2: MANDORLE | AA2: 978 | AB2: SGUSCIATE TOSTATE | AC2: 180 | AD2: 5 | AE2: PRODOTTI DI BARTOLO | AF2: 1 | AG2: PRODOTTO FINITO | AH2: 70 | AJ2: OA-25-3199 | AK2: 45981 | AL2: No | AM2: 1 | AQ2: =_xlfn.CONCAT(C2,"/",D2) -> 557/800 | AR2: =IF(D2=0,"DA CONTRATTO","SPOT") -> SPOT | AS2: =IF(AD2=5,"P","C") -> P | AT2: =VLOOKUP(S2,'FILE PALLETTIZZAZIONI DB SRL'!B:H,5,FALSE) -> 2 | AU2: =TEXT(N2,"gggg") -> sabato | AV2: =WEEKNUM(N2) -> 0 | AW2: =IF(AND(ISBLANK(N2),AS2="P"), "ATTENZIONE: Data produzione non pianificata", IF(AND(ISBLANK(N2),AS2="C"), "ATTENZIONE: Data arrivo merce acquisti non presente", IF(O2-N2>=AP2, "Data sped. utile INSERITA", "ATTENZIONE: GG. resa non adeguati"))) -> ATTENZIONE: Data produzione non pianificata | AX2: =IF(ISBLANK(O2), "ATTENZIONE: Data non inserita", IF(O2<=param!B2, "ATTENZIONE: Ritardo, Avvertire il cliente", "Data cons. rich. INSERITA")) -> Data cons. rich. INSERITA | AY2: =IF(OR(ISBLANK(AP2),ISBLANK(AH2)), "ATTENZIONE: Vettore non associato", IF(V2="VETTORE", "Tipo spedizione: VETTORE", IF(V2="DESTINATARIO", "Tipo spedizione: DESTINATARIO", IF(ISBLANK(V2), "ATTENZIONE: Vettore vuoto", "?")))) -> ATTENZIONE: Vettore non associato | AZ2: =IF(AM2=1, "Città OK", "ATTENZIONE: CAP non presente") -> Città OK | BA2: ATTENZIONE: Giorno congruo presa vettore | BB2: =_xlfn.CONCAT(AW2," - ",AX2," - ",AY2," - ",AZ2," - ","Data: ",BA2) -> ATTENZIONE: Data produzione non pianificata - Data cons. rich. INSERITA - ATTENZIONE: Vettore non associato - Città OK - Data: ATTENZIONE: Giorno congruo presa vettore
A3: S | B3: 2 | C3: 802 | D3: 0 | E3: 45975 | F3: 64 | G3: BARATTI & MILANO SRL | H3: GRPP40224/GP22 | I3: B21924/GP22 | J3: GRANELLA DI PISTACCHI PRALINATA ARTIG. 407 CAL.2/4 | K3: 3072 | M3: 3072 | O3: 46001 | P3: TRASPORTI RECUPERO SRL | Q3: 8 | R3: 10 | S3: GP22 | T3: Non evaso | U3: DDP | V3: VETTORE | W3: BARATTI & MILANO SRL | X3: 12042 BRA CN | Y3: 5 | Z3: GRANELLE PRALINATE | AA3: 216 | AB3: PISTACCHI | AC3: 125 | AD3: 5 | AE3: PRODOTTI DI BARTOLO | AF3: 1 | AG3: PRODOTTO FINITO | AH3: 70 | AJ3: 802/OP | AL3: No | AM3: 1 | AQ3: =_xlfn.CONCAT(C3,"/",D3) -> 802/0 | AR3: =IF(D3=0,"DA CONTRATTO","SPOT") -> DA CONTRATTO | AS3: =IF(AD3=5,"P","C") -> P | AT3: =VLOOKUP(S3,'FILE PALLETTIZZAZIONI DB SRL'!B:H,5,FALSE) -> 2 | AU3: =TEXT(N3,"gggg") -> sabato | AV3: =WEEKNUM(N3) -> 0 | AW3: =IF(AND(ISBLANK(N3),AS3="P"), "ATTENZIONE: Data produzione non pianificata", IF(AND(ISBLANK(N3),AS3="C"), "ATTENZIONE: Data arrivo merce acquisti non presente", IF(O3-N3>=AP3, "Data sped. utile INSERITA", "ATTENZIONE: GG. resa non adeguati"))) -> ATTENZIONE: Data produzione non pianificata | AX3: =IF(ISBLANK(O3), "ATTENZIONE: Data non inserita", IF(O3<=param!B2, "ATTENZIONE: Ritardo, Avvertire il cliente", "Data cons. rich. INSERITA")) -> Data cons. rich. INSERITA | AY3: =IF(OR(ISBLANK(AP3),ISBLANK(AH3)), "ATTENZIONE: Vettore non associato", IF(V3="VETTORE", "Tipo spedizione: VETTORE", IF(V3="DESTINATARIO", "Tipo spedizione: DESTINATARIO", IF(ISBLANK(V3), "ATTENZIONE: Vettore vuoto", "?")))) -> ATTENZIONE: Vettore non associato | AZ3: =IF(AM3=1, "Città OK", "ATTENZIONE: CAP non presente") -> Città OK | BA3: ATTENZIONE: Giorno congruo presa vettore | BB3: =_xlfn.CONCAT(AW3," - ",AX3," - ",AY3," - ",AZ3," - ","Data: ",BA3) -> ATTENZIONE: Data produzione non pianificata - Data cons. rich. INSERITA - ATTENZIONE: Vettore non associato - Città OK - Data: ATTENZIONE: Giorno congruo presa vettore
A4: S | B4: 3 | C4: 563 | D4: 800 | E4: 45972 | F4: 64 | G4: BARATTI & MILANO SRL | H4: PMPT2071/P11 | I4: B21905/P11 | J4: PASTA DI MANDORLE PELATE TOSTATE B21905 | K4: 1000 | M4: 1000 | O4: 46001 | P4: RUSTICO BRUNO | Q4: 8 | R4: 10 | S4: P11 | T4: Non evaso | U4: DDP | V4: VETTORE | W4: BARATTI & MILANO SRL | X4: 12042 BRA CN | Y4: 5 | Z4: PASTE | AA4: 213 | AB4: MANDORLE | AC4: 235 | AD4: 5 | AE4: PRODOTTI DI BARTOLO | AF4: 1 | AG4: PRODOTTO FINITO | AH4: 1 | AJ4: 563/OP | AK4: 45982 | AL4: No | AM4: 1 | AN4: martedì | AO4: venerdì | AP4: 5 | AQ4: =_xlfn.CONCAT(C4,"/",D4) -> 563/800 | AR4: =IF(D4=0,"DA CONTRATTO","SPOT") -> SPOT | AS4: =IF(AD4=5,"P","C") -> P | AT4: =VLOOKUP(S4,'FILE PALLETTIZZAZIONI DB SRL'!B:H,5,FALSE) -> 2 | AU4: =TEXT(N4,"gggg") -> sabato | AV4: =WEEKNUM(N4) -> 0 | AW4: =IF(AND(ISBLANK(N4),AS4="P"), "ATTENZIONE: Data produzione non pianificata", IF(AND(ISBLANK(N4),AS4="C"), "ATTENZIONE: Data arrivo merce acquisti non presente", IF(O4-N4>=AP4, "Data sped. utile INSERITA", "ATTENZIONE: GG. resa non adeguati"))) -> ATTENZIONE: Data produzione non pianificata | AX4: =IF(ISBLANK(O4), "ATTENZIONE: Data non inserita", IF(O4<=param!B2, "ATTENZIONE: Ritardo, Avvertire il cliente", "Data cons. rich. INSERITA")) -> Data cons. rich. INSERITA | AY4: =IF(OR(ISBLANK(AP4),ISBLANK(AH4)), "ATTENZIONE: Vettore non associato", IF(V4="VETTORE", "Tipo spedizione: VETTORE", IF(V4="DESTINATARIO", "Tipo spedizione: DESTINATARIO", IF(ISBLANK(V4), "ATTENZIONE: Vettore vuoto", "?")))) -> Tipo spedizione: VETTORE | AZ4: =IF(AM4=1, "Città OK", "ATTENZIONE: CAP non presente") -> Città OK | BA4: ATTENZIONE: Giorno congruo presa vettore | BB4: =_xlfn.CONCAT(AW4," - ",AX4," - ",AY4," - ",AZ4," - ","Data: ",BA4) -> ATTENZIONE: Data produzione non pianificata - Data cons. rich. INSERITA - Tipo spedizione: VETTORE - Città OK - Data: ATTENZIONE: Giorno congruo presa vettore
A5: S | B5: 4 | C5: 244 | D5: 0 | E5: 45713 | F5: 113 | G5: SIGEL GELATI S.R.L. | H5: MPMPT212/CT20 | I5: MPT212/CT20 | J5: MANDORLE PELATE TOSTATE CAL. 34/36 | K5: 640 | M5: 640 | P5: RUSTICO BRUNO | Q5: 8 | R5: 10 | S5: CT20 | T5: Non evaso | U5: DDP | V5: VETTORE | W5: SIGEL GELATI S.R.L. | X5: 91025 MARSALA TP | Y5: 4 | Z5: MANDORLE | AA5: 830 | AB5: PELATE TOSTATE | AC5: 180 | AD5: 4 | AE5: PRODOTTI COMMERCIALIZZATI | AF5: 1 | AG5: PRODOTTO FINITO | AH5: 1 | AJ5: EMAIL 11/02/25 | AL5: No | AM5: 1 | AN5: martedì | AO5: venerdì | AP5: 5 | AQ5: =_xlfn.CONCAT(C5,"/",D5) -> 244/0 | AR5: =IF(D5=0,"DA CONTRATTO","SPOT") -> DA CONTRATTO | AS5: =IF(AD5=5,"P","C") -> C | AT5: =VLOOKUP(S5,'FILE PALLETTIZZAZIONI DB SRL'!B:H,5,FALSE) -> 1 | AU5: =TEXT(N5,"gggg") -> sabato | AV5: =WEEKNUM(N5) -> 0 | AW5: =IF(AND(ISBLANK(N5),AS5="P"), "ATTENZIONE: Data produzione non pianificata", IF(AND(ISBLANK(N5),AS5="C"), "ATTENZIONE: Data arrivo merce acquisti non presente", IF(O5-N5>=AP5, "Data sped. utile INSERITA", "ATTENZIONE: GG. resa non adeguati"))) -> ATTENZIONE: Data arrivo merce acquisti non presente | AX5: =IF(ISBLANK(O5), "ATTENZIONE: Data non inserita", IF(O5<=param!B2, "ATTENZIONE: Ritardo, Avvertire il cliente", "Data cons. rich. INSERITA")) -> ATTENZIONE: Data non inserita | AY5: =IF(OR(ISBLANK(AP5),ISBLANK(AH5)), "ATTENZIONE: Vettore non associato", IF(V5="VETTORE", "Tipo spedizione: VETTORE", IF(V5="DESTINATARIO", "Tipo spedizione: DESTINATARIO", IF(ISBLANK(V5), "ATTENZIONE: Vettore vuoto", "?")))) -> Tipo spedizione: VETTORE | AZ5: =IF(AM5=1, "Città OK", "ATTENZIONE: CAP non presente") -> Città OK | BA5: ATTENZIONE: Giorno congruo presa vettore | BB5: =_xlfn.CONCAT(AW5," - ",AX5," - ",AY5," - ",AZ5," - ","Data: ",BA5) -> ATTENZIONE: Data arrivo merce acquisti non presente - ATTENZIONE: Data non inserita - Tipo spedizione: VETTORE - Città OK - Data: ATTENZIONE: Giorno congruo presa vettore
A6: S | B6: 5 | C6: 266 | D6: 0 | E6: 45715 | F6: 113 | G6: SIGEL GELATI S.R.L. | H6: MPMPT212/CT20 | I6: MPT212/CT20 | J6: MANDORLE PELATE TOSTATE CAL. 34/36 | K6: 640 | M6: 640 | P6: RUSTICO BRUNO | Q6: 8 | R6: 10 | S6: CT20 | T6: Non evaso | U6: DDP | V6: VETTORE | W6: SIGEL GELATI S.R.L. | X6: 91025 MARSALA TP | Y6: 4 | Z6: MANDORLE | AA6: 830 | AB6: PELATE TOSTATE | AC6: 180 | AD6: 4 | AE6: PRODOTTI COMMERCIALIZZATI | AF6: 1 | AG6: PRODOTTO FINITO | AH6: 1 | AJ6: EMAIL 11/02/25 | AL6: No | AM6: 1 | AN6: martedì | AO6: venerdì | AP6: 5 | AQ6: =_xlfn.CONCAT(C6,"/",D6) -> 266/0 | AR6: =IF(D6=0,"DA CONTRATTO","SPOT") -> DA CONTRATTO | AS6: =IF(AD6=5,"P","C") -> C | AT6: =VLOOKUP(S6,'FILE PALLETTIZZAZIONI DB SRL'!B:H,5,FALSE) -> 1 | AU6: =TEXT(N6,"gggg") -> sabato | AV6: =WEEKNUM(N6) -> 0 | AW6: =IF(AND(ISBLANK(N6),AS6="P"), "ATTENZIONE: Data produzione non pianificata", IF(AND(ISBLANK(N6),AS6="C"), "ATTENZIONE: Data arrivo merce acquisti non presente", IF(O6-N6>=AP6, "Data sped. utile INSERITA", "ATTENZIONE: GG. resa non adeguati"))) -> ATTENZIONE: Data arrivo merce acquisti non presente | AX6: =IF(ISBLANK(O6), "ATTENZIONE: Data non inserita", IF(O6<=param!B2, "ATTENZIONE: Ritardo, Avvertire il cliente", "Data cons. rich. INSERITA")) -> ATTENZIONE: Data non inserita | AY6: =IF(OR(ISBLANK(AP6),ISBLANK(AH6)), "ATTENZIONE: Vettore non associato", IF(V6="VETTORE", "Tipo spedizione: VETTORE", IF(V6="DESTINATARIO", "Tipo spedizione: DESTINATARIO", IF(ISBLANK(V6), "ATTENZIONE: Vettore vuoto", "?")))) -> Tipo spedizione: VETTORE | AZ6: =IF(AM6=1, "Città OK", "ATTENZIONE: CAP non presente") -> Città OK | BA6: ATTENZIONE: Giorno congruo presa vettore | BB6: =_xlfn.CONCAT(AW6," - ",AX6," - ",AY6," - ",AZ6," - ","Data: ",BA6) -> ATTENZIONE: Data arrivo merce acquisti non presente - ATTENZIONE: Data non inserita - Tipo spedizione: VETTORE - Città OK - Data: ATTENZIONE: Giorno congruo presa vettore
A7: S | B7: 6 | C7: 768 | D7: 0 | E7: 45958 | F7: 284 | G7: LA SUISSA S.R.L. | H7: MPGRMPT50625SAL/B500 | I7: AFR753010/B500 | J7: Granella di Mandorle Pel Tost Sal E Grande | K7: 0.5 | M7: 0.5 | O7: 45980 | P7: TRASPORTI RECUPERO SRL | Q7: 8 | R7: 10 | S7: BSV500 | T7: Evaso parzialmente | U7: DDP | V7: VETTORE | W7: LA SUISSA | X7: 15061 ARQUATA SCRIVIA | Y7: 4 | Z7: GRANELLE | AA7: 199 | AB7: MANDORLE PELATE TOSTATE | AC7: 120 | AD7: 4 | AE7: PRODOTTI COMMERCIALIZZATI | AF7: 1 | AG7: PRODOTTO FINITO | AH7: 70 | AJ7: LCO2501058 | AL7: No | AM7: 1 | AQ7: =_xlfn.CONCAT(C7,"/",D7) -> 768/0 | AR7: =IF(D7=0,"DA CONTRATTO","SPOT") -> DA CONTRATTO | AS7: =IF(AD7=5,"P","C") -> C | AT7: =VLOOKUP(S7,'FILE PALLETTIZZAZIONI DB SRL'!B:H,5,FALSE) -> #N/A | AU7: =TEXT(N7,"gggg") -> sabato | AV7: =WEEKNUM(N7) -> 0 | AW7: =IF(AND(ISBLANK(N7),AS7="P"), "ATTENZIONE: Data produzione non pianificata", IF(AND(ISBLANK(N7),AS7="C"), "ATTENZIONE: Data arrivo merce acquisti non presente", IF(O7-N7>=AP7, "Data sped. utile INSERITA", "ATTENZIONE: GG. resa non adeguati"))) -> ATTENZIONE: Data arrivo merce acquisti non presente | AX7: =IF(ISBLANK(O7), "ATTENZIONE: Data non inserita", IF(O7<=param!B2, "ATTENZIONE: Ritardo, Avvertire il cliente", "Data cons. rich. INSERITA")) -> Data cons. rich. INSERITA | AY7: =IF(OR(ISBLANK(AP7),ISBLANK(AH7)), "ATTENZIONE: Vettore non associato", IF(V7="VETTORE", "Tipo spedizione: VETTORE", IF(V7="DESTINATARIO", "Tipo spedizione: DESTINATARIO", IF(ISBLANK(V7), "ATTENZIONE: Vettore vuoto", "?")))) -> ATTENZIONE: Vettore non associato | AZ7: =IF(AM7=1, "Città OK", "ATTENZIONE: CAP non presente") -> Città OK | BA7: ATTENZIONE: Giorno congruo presa vettore | BB7: =_xlfn.CONCAT(AW7," - ",AX7," - ",AY7," - ",AZ7," - ","Data: ",BA7) -> ATTENZIONE: Data arrivo merce acquisti non presente - Data cons. rich. INSERITA - ATTENZIONE: Vettore non associato - Città OK - Data: ATTENZIONE: Giorno congruo presa vettore
A8: S | B8: 7 | C8: 770 | D8: 0 | E8: 45958 | F8: 284 | G8: LA SUISSA S.R.L. | H8: MPGRMPT50825SAL/G21 | I8: AFR753110/G21 | J8: Granella di Mandorle Pel. Tostate Salate IT Grande | K8: 640 | L8: 340 | M8: 300 | O8: 45986 | P8: CURRO' TRASPORTI SRL | Q8: 8 | R8: 10 | S8: G21 | T8: Evaso parzialmente | U8: DDP | V8: VETTORE | W8: LA SUISSA | X8: 15061 ARQUATA SCRIVIA | Y8: 4 | Z8: GRANELLE | AA8: 199 | AB8: MANDORLE PELATE TOSTATE | AC8: 120 | AD8: 4 | AE8: PRODOTTI COMMERCIALIZZATI | AF8: 1 | AG8: PRODOTTO FINITO | AH8: 2 | AJ8: LCO2501060 | AL8: No | AM8: 1 | AQ8: =_xlfn.CONCAT(C8,"/",D8) -> 770/0 | AR8: =IF(D8=0,"DA CONTRATTO","SPOT") -> DA CONTRATTO | AS8: =IF(AD8=5,"P","C") -> C | AT8: =VLOOKUP(S8,'FILE PALLETTIZZAZIONI DB SRL'!B:H,5,FALSE) -> 2 | AU8: =TEXT(N8,"gggg") -> sabato | AV8: =WEEKNUM(N8) -> 0 | AW8: =IF(AND(ISBLANK(N8),AS8="P"), "ATTENZIONE: Data produzione non pianificata", IF(AND(ISBLANK(N8),AS8="C"), "ATTENZIONE: Data arrivo merce acquisti non presente", IF(O8-N8>=AP8, "Data sped. utile INSERITA", "ATTENZIONE: GG. resa non adeguati"))) -> ATTENZIONE: Data arrivo merce acquisti non presente | AX8: =IF(ISBLANK(O8), "ATTENZIONE: Data non inserita", IF(O8<=param!B2, "ATTENZIONE: Ritardo, Avvertire il cliente", "Data cons. rich. INSERITA")) -> Data cons. rich. INSERITA | AY8: =IF(OR(ISBLANK(AP8),ISBLANK(AH8)), "ATTENZIONE: Vettore non associato", IF(V8="VETTORE", "Tipo spedizione: VETTORE", IF(V8="DESTINATARIO", "Tipo spedizione: DESTINATARIO", IF(ISBLANK(V8), "ATTENZIONE: Vettore vuoto", "?")))) -> ATTENZIONE: Vettore non associato | AZ8: =IF(AM8=1, "Città OK", "ATTENZIONE: CAP non presente") -> Città OK | BA8: ATTENZIONE: Giorno congruo presa vettore | BB8: =_xlfn.CONCAT(AW8," - ",AX8," - ",AY8," - ",AZ8," - ","Data: ",BA8) -> ATTENZIONE: Data arrivo merce acquisti non presente - Data cons. rich. INSERITA - ATTENZIONE: Vettore non associato - Città OK - Data: ATTENZIONE: Giorno congruo presa vettore
A9: S | B9: 8 | C9: 770 | D9: 0 | E9: 45958 | F9: 284 | G9: LA SUISSA S.R.L. | H9: MPGRMPT50825SAL/B500 | I9: AFR753110/BSV500 | J9: Granella di Mandorle Pel. Tostate Salate IT Grande | K9: 0.5 | M9: 0.5 | O9: 45986 | P9: CURRO' TRASPORTI SRL | Q9: 8 | R9: 10 | S9: BSV500 | T9: Evaso parzialmente | U9: DDP | V9: VETTORE | W9: LA SUISSA | X9: 15061 ARQUATA SCRIVIA | Y9: 4 | Z9: GRANELLE | AA9: 199 | AB9: MANDORLE PELATE TOSTATE | AC9: 120 | AD9: 4 | AE9: PRODOTTI COMMERCIALIZZATI | AF9: 1 | AG9: PRODOTTO FINITO | AH9: 2 | AJ9: LCO2501060 | AL9: No | AM9: 1 | AQ9: =_xlfn.CONCAT(C9,"/",D9) -> 770/0 | AR9: =IF(D9=0,"DA CONTRATTO","SPOT") -> DA CONTRATTO | AS9: =IF(AD9=5,"P","C") -> C | AT9: =VLOOKUP(S9,'FILE PALLETTIZZAZIONI DB SRL'!B:H,5,FALSE) -> #N/A | AU9: =TEXT(N9,"gggg") -> sabato | AV9: =WEEKNUM(N9) -> 0 | AW9: =IF(AND(ISBLANK(N9),AS9="P"), "ATTENZIONE: Data produzione non pianificata", IF(AND(ISBLANK(N9),AS9="C"), "ATTENZIONE: Data arrivo merce acquisti non presente", IF(O9-N9>=AP9, "Data sped. utile INSERITA", "ATTENZIONE: GG. resa non adeguati"))) -> ATTENZIONE: Data arrivo merce acquisti non presente | AX9: =IF(ISBLANK(O9), "ATTENZIONE: Data non inserita", IF(O9<=param!B2, "ATTENZIONE: Ritardo, Avvertire il cliente", "Data cons. rich. INSERITA")) -> Data cons. rich. INSERITA | AY9: =IF(OR(ISBLANK(AP9),ISBLANK(AH9)), "ATTENZIONE: Vettore non associato", IF(V9="VETTORE", "Tipo spedizione: VETTORE", IF(V9="DESTINATARIO", "Tipo spedizione: DESTINATARIO", IF(ISBLANK(V9), "ATTENZIONE: Vettore vuoto", "?")))) -> ATTENZIONE: Vettore non associato | AZ9: =IF(AM9=1, "Città OK", "ATTENZIONE: CAP non presente") -> Città OK | BA9: ATTENZIONE: Giorno congruo presa vettore | BB9: =_xlfn.CONCAT(AW9," - ",AX9," - ",AY9," - ",AZ9," - ","Data: ",BA9) -> ATTENZIONE: Data arrivo merce acquisti non presente - Data cons. rich. INSERITA - ATTENZIONE: Vettore non associato - Città OK - Data: ATTENZIONE: Giorno congruo presa vettore
A10: S | B10: 9 | C10: 796 | D10: 0 | E10: 45972 | F10: 284 | G10: LA SUISSA S.R.L. | H10: GRPM41368/GP22 | I10: AFR753112/GP22 | J10: GRANELLA DI MANDORLA SGUSCIATE PRALINATE 6-8 MM | K10: 1296 | M10: 1296 | N10: 45996 | O10: 46003 | P10: RUSTICO BRUNO | Q10: 8 | R10: 10 | S10: GP22 | T10: Non evaso | U10: DDP | V10: VETTORE | W10: LA SUISSA | X10: 15061 ARQUATA SCRIVIA | Y10: 5 | Z10: GRANELLE PRALINATE | AA10: 213 | AB10: MANDORLE | AC10: 125 | AD10: 5 | AE10: PRODOTTI DI BARTOLO | AF10: 1 | AG10: PRODOTTO FINITO | AH10: 1 | AJ10: LCO2501152 | AL10: No | AM10: 1 | AN10: martedì | AO10: venerdì | AP10: 5 | AQ10: =_xlfn.CONCAT(C10,"/",D10) -> 796/0 | AR10: =IF(D10=0,"DA CONTRATTO","SPOT") -> DA CONTRATTO | AS10: =IF(AD10=5,"P","C") -> P | AT10: =VLOOKUP(S10,'FILE PALLETTIZZAZIONI DB SRL'!B:H,5,FALSE) -> 2 | AU10: =TEXT(N10,"gggg") -> venerdì | AV10: =WEEKNUM(N10) -> 49 | AW10: =IF(AND(ISBLANK(N10),AS10="P"), "ATTENZIONE: Data produzione non pianificata", IF(AND(ISBLANK(N10),AS10="C"), "ATTENZIONE: Data arrivo merce acquisti non presente", IF(O10-N10>=AP10, "Data sped. utile INSERITA", "ATTENZIONE: GG. resa non adeguati"))) -> Data sped. utile INSERITA | AX10: =IF(ISBLANK(O10), "ATTENZIONE: Data non inserita", IF(O10<=param!B2, "ATTENZIONE: Ritardo, Avvertire il cliente", "Data cons. rich. INSERITA")) -> Data cons. rich. INSERITA | AY10: =IF(OR(ISBLANK(AP10),ISBLANK(AH10)), "ATTENZIONE: Vettore non associato", IF(V10="VETTORE", "Tipo spedizione: VETTORE", IF(V10="DESTINATARIO", "Tipo spedizione: DESTINATARIO", IF(ISBLANK(V10), "ATTENZIONE: Vettore vuoto", "?")))) -> Tipo spedizione: VETTORE | AZ10: =IF(AM10=1, "Città OK", "ATTENZIONE: CAP non presente") -> Città OK | BA10: OK | BB10: =_xlfn.CONCAT(AW10," - ",AX10," - ",AY10," - ",AZ10," - ","Data: ",BA10) -> Data sped. utile INSERITA - Data cons. rich. INSERITA - Tipo spedizione: VETTORE - Città OK - Data: OK
A11: S | B11: 10 | C11: 796 | D11: 0 | E11: 45972 | F11: 284 | G11: LA SUISSA S.R.L. | H11: GRPM41368/BSV500 | I11: AFR753112/BSV500 | J11: GRANELLA DI MANDORLA SGUSCIATE PRALINATE 6-8 MM | K11: 0.5 | M11: 0.5 | N11: 45996 | O11: 46003 | P11: RUSTICO BRUNO | Q11: 8 | R11: 10 | S11: BSV500 | T11: Non evaso | U11: DDP | V11: VETTORE | W11: LA SUISSA | X11: 15061 ARQUATA SCRIVIA | Y11: 5 | Z11: GRANELLE PRALINATE | AA11: 213 | AB11: MANDORLE | AC11: 125 | AD11: 5 | AE11: PRODOTTI DI BARTOLO | AF11: 1 | AG11: PRODOTTO FINITO | AH11: 1 | AJ11: LCO2501152 | AL11: No | AM11: 1 | AN11: martedì | AO11: venerdì | AP11: 5 | AQ11: =_xlfn.CONCAT(C11,"/",D11) -> 796/0 | AR11: =IF(D11=0,"DA CONTRATTO","SPOT") -> DA CONTRATTO | AS11: =IF(AD11=5,"P","C") -> P | AT11: =VLOOKUP(S11,'FILE PALLETTIZZAZIONI DB SRL'!B:H,5,FALSE) -> #N/A | AU11: =TEXT(N11,"gggg") -> venerdì | AV11: =WEEKNUM(N11) -> 49 | AW11: =IF(AND(ISBLANK(N11),AS11="P"), "ATTENZIONE: Data produzione non pianificata", IF(AND(ISBLANK(N11),AS11="C"), "ATTENZIONE: Data arrivo merce acquisti non presente", IF(O11-N11>=AP11, "Data sped. utile INSERITA", "ATTENZIONE: GG. resa non adeguati"))) -> Data sped. utile INSERITA | AX11: =IF(ISBLANK(O11), "ATTENZIONE: Data non inserita", IF(O11<=param!B2, "ATTENZIONE: Ritardo, Avvertire il cliente", "Data cons. rich. INSERITA")) -> Data cons. rich. INSERITA | AY11: =IF(OR(ISBLANK(AP11),ISBLANK(AH11)), "ATTENZIONE: Vettore non associato", IF(V11="VETTORE", "Tipo spedizione: VETTORE", IF(V11="DESTINATARIO", "Tipo spedizione: DESTINATARIO", IF(ISBLANK(V11), "ATTENZIONE: Vettore vuoto", "?")))) -> Tipo spedizione: VETTORE | AZ11: =IF(AM11=1, "Città OK", "ATTENZIONE: CAP non presente") -> Città OK | BA11: OK | BB11: =_xlfn.CONCAT(AW11," - ",AX11," - ",AY11," - ",AZ11," - ","Data: ",BA11) -> Data sped. utile INSERITA - Data cons. rich. INSERITA - Tipo spedizione: VETTORE - Città OK - Data: OK
A12: S | B12: 11 | C12: 797 | D12: 0 | E12: 45972 | F12: 284 | G12: LA SUISSA S.R.L. | H12: MPGRMPT50825SAL/G21 | I12: AFR753110/G21 | J12: Granella di Mandorle Pel. Tostate Salate IT Grande | K12: 640 | M12: 640 | O12: 46001 | P12: CURRO' TRASPORTI SRL | Q12: 8 | R12: 10 | S12: G21 | T12: Non evaso | U12: DDP | V12: VETTORE | W12: LA SUISSA | X12: 15061 ARQUATA SCRIVIA | Y12: 4 | Z12: GRANELLE | AA12: 199 | AB12: MANDORLE PELATE TOSTATE | AC12: 120 | AD12: 4 | AE12: PRODOTTI COMMERCIALIZZATI | AF12: 1 | AG12: PRODOTTO FINITO | AH12: 2 | AJ12: LCO2501153 | AL12: No | AM12: 1 | AQ12: =_xlfn.CONCAT(C12,"/",D12) -> 797/0 | AR12: =IF(D12=0,"DA CONTRATTO","SPOT") -> DA CONTRATTO | AS12: =IF(AD12=5,"P","C") -> C | AT12: =VLOOKUP(S12,'FILE PALLETTIZZAZIONI DB SRL'!B:H,5,FALSE) -> 2 | AU12: =TEXT(N12,"gggg") -> sabato | AV12: =WEEKNUM(N12) -> 0 | AW12: =IF(AND(ISBLANK(N12),AS12="P"), "ATTENZIONE: Data produzione non pianificata", IF(AND(ISBLANK(N12),AS12="C"), "ATTENZIONE: Data arrivo merce acquisti non presente", IF(O12-N12>=AP12, "Data sped. utile INSERITA", "ATTENZIONE: GG. resa non adeguati"))) -> ATTENZIONE: Data arrivo merce acquisti non presente | AX12: =IF(ISBLANK(O12), "ATTENZIONE: Data non inserita", IF(O12<=param!B2, "ATTENZIONE: Ritardo, Avvertire il cliente", "Data cons. rich. INSERITA")) -> Data cons. rich. INSERITA | AY12: =IF(OR(ISBLANK(AP12),ISBLANK(AH12)), "ATTENZIONE: Vettore non associato", IF(V12="VETTORE", "Tipo spedizione: VETTORE", IF(V12="DESTINATARIO", "Tipo spedizione: DESTINATARIO", IF(ISBLANK(V12), "ATTENZIONE: Vettore vuoto", "?")))) -> ATTENZIONE: Vettore non associato | AZ12: =IF(AM12=1, "Città OK", "ATTENZIONE: CAP non presente") -> Città OK | BA12: ATTENZIONE: Giorno congruo presa vettore | BB12: =_xlfn.CONCAT(AW12," - ",AX12," - ",AY12," - ",AZ12," - ","Data: ",BA12) -> ATTENZIONE: Data arrivo merce acquisti non presente - Data cons. rich. INSERITA - ATTENZIONE: Vettore non associato - Città OK - Data: ATTENZIONE: Giorno congruo presa vettore
A13: S | B13: 12 | C13: 797 | D13: 0 | E13: 45972 | F13: 284 | G13: LA SUISSA S.R.L. | H13: MPGRMPT50825SAL/B500 | I13: AFR753110/BSV500 | J13: Granella di Mandorle Pel. Tostate Salate IT Grande | K13: 0.5 | M13: 0.5 | O13: 46001 | P13: CURRO' TRASPORTI SRL | Q13: 8 | R13: 10 | S13: BSV500 | T13: Non evaso | U13: DDP | V13: VETTORE | W13: LA SUISSA | X13: 15061 ARQUATA SCRIVIA | Y13: 4 | Z13: GRANELLE | AA13: 199 | AB13: MANDORLE PELATE TOSTATE | AC13: 120 | AD13: 4 | AE13: PRODOTTI COMMERCIALIZZATI | AF13: 1 | AG13: PRODOTTO FINITO | AH13: 2 | AJ13: LCO2501153 | AL13: No | AM13: 1 | AQ13: =_xlfn.CONCAT(C13,"/",D13) -> 797/0 | AR13: =IF(D13=0,"DA CONTRATTO","SPOT") -> DA CONTRATTO | AS13: =IF(AD13=5,"P","C") -> C | AT13: =VLOOKUP(S13,'FILE PALLETTIZZAZIONI DB SRL'!B:H,5,FALSE) -> #N/A | AU13: =TEXT(N13,"gggg") -> sabato | AV13: =WEEKNUM(N13) -> 0 | AW13: =IF(AND(ISBLANK(N13),AS13="P"), "ATTENZIONE: Data produzione non pianificata", IF(AND(ISBLANK(N13),AS13="C"), "ATTENZIONE: Data arrivo merce acquisti non presente", IF(O13-N13>=AP13, "Data sped. utile INSERITA", "ATTENZIONE: GG. resa non adeguati"))) -> ATTENZIONE: Data arrivo merce acquisti non presente | AX13: =IF(ISBLANK(O13), "ATTENZIONE: Data non inserita", IF(O13<=param!B2, "ATTENZIONE: Ritardo, Avvertire il cliente", "Data cons. rich. INSERITA")) -> Data cons. rich. INSERITA | AY13: =IF(OR(ISBLANK(AP13),ISBLANK(AH13)), "ATTENZIONE: Vettore non associato", IF(V13="VETTORE", "Tipo spedizione: VETTORE", IF(V13="DESTINATARIO", "Tipo spedizione: DESTINATARIO", IF(ISBLANK(V13), "ATTENZIONE: Vettore vuoto", "?")))) -> ATTENZIONE: Vettore non associato | AZ13: =IF(AM13=1, "Città OK", "ATTENZIONE: CAP non presente") -> Città OK | BA13: ATTENZIONE: Giorno congruo presa vettore | BB13: =_xlfn.CONCAT(AW13," - ",AX13," - ",AY13," - ",AZ13," - ","Data: ",BA13) -> ATTENZIONE: Data arrivo merce acquisti non presente - Data cons. rich. INSERITA - ATTENZIONE: Vettore non associato - Città OK - Data: ATTENZIONE: Giorno congruo presa vettore
A14: S | B14: 13 | C14: 798 | D14: 0 | E14: 45972 | F14: 284 | G14: LA SUISSA S.R.L. | H14: GRPSTS51125SAL/G21 | I14: AFR753111/G21 | J14: Granella di Pistacchi Sg. Tostati Salati IT Grande | K14: 640 | M14: 640 | N14: 45996 | O14: 46001 | P14: CURRO' TRASPORTI SRL | Q14: 8 | R14: 10 | S14: G21 | T14: Non evaso | U14: DDP | V14: VETTORE | W14: LA SUISSA | X14: 15061 ARQUATA SCRIVIA | Y14: 5 | Z14: GRANELLE | AA14: 208 | AB14: PISTACCHI SGUSCIATI TOSTAT | AC14: 120 | AD14: 5 | AE14: PRODOTTI DI BARTOLO | AF14: 1 | AG14: PRODOTTO FINITO | AH14: 2 | AJ14: LCO2501154 | AL14: No | AM14: 1 | AQ14: =_xlfn.CONCAT(C14,"/",D14) -> 798/0 | AR14: =IF(D14=0,"DA CONTRATTO","SPOT") -> DA CONTRATTO | AS14: =IF(AD14=5,"P","C") -> P | AT14: =VLOOKUP(S14,'FILE PALLETTIZZAZIONI DB SRL'!B:H,5,FALSE) -> 2 | AU14: =TEXT(N14,"gggg") -> venerdì | AV14: =WEEKNUM(N14) -> 49 | AW14: =IF(AND(ISBLANK(N14),AS14="P"), "ATTENZIONE: Data produzione non pianificata", IF(AND(ISBLANK(N14),AS14="C"), "ATTENZIONE: Data arrivo merce acquisti non presente", IF(O14-N14>=AP14, "Data sped. utile INSERITA", "ATTENZIONE: GG. resa non adeguati"))) -> Data sped. utile INSERITA | AX14: =IF(ISBLANK(O14), "ATTENZIONE: Data non inserita", IF(O14<=param!B2, "ATTENZIONE: Ritardo, Avvertire il cliente", "Data cons. rich. INSERITA")) -> Data cons. rich. INSERITA | AY14: =IF(OR(ISBLANK(AP14),ISBLANK(AH14)), "ATTENZIONE: Vettore non associato", IF(V14="VETTORE", "Tipo spedizione: VETTORE", IF(V14="DESTINATARIO", "Tipo spedizione: DESTINATARIO", IF(ISBLANK(V14), "ATTENZIONE: Vettore vuoto", "?")))) -> ATTENZIONE: Vettore non associato | AZ14: =IF(AM14=1, "Città OK", "ATTENZIONE: CAP non presente") -> Città OK | BA14: ATTENZIONE: Giorno congruo presa vettore | BB14: =_xlfn.CONCAT(AW14," - ",AX14," - ",AY14," - ",AZ14," - ","Data: ",BA14) -> Data sped. utile INSERITA - Data cons. rich. INSERITA - ATTENZIONE: Vettore non associato - Città OK - Data: ATTENZIONE: Giorno congruo presa vettore
A15: S | B15: 14 | C15: 798 | D15: 0 | E15: 45972 | F15: 284 | G15: LA SUISSA S.R.L. | H15: GRPSTS51125SAL/B500 | I15: AFR753111/B500 | J15: Granella di Pistacchi Sg. Tostati Salati IT Grande | K15: 0.5 | M15: 0.5 | N15: 45996 | O15: 46001 | P15: CURRO' TRASPORTI SRL | Q15: 8 | R15: 10 | S15: BSV500 | T15: Non evaso | U15: DDP | V15: VETTORE | W15: LA SUISSA | X15: 15061 ARQUATA SCRIVIA | Y15: 5 | Z15: GRANELLE | AA15: 208 | AB15: PISTACCHI SGUSCIATI TOSTAT | AC15: 120 | AD15: 5 | AE15: PRODOTTI DI BARTOLO | AF15: 1 | AG15: PRODOTTO FINITO | AH15: 2 | AJ15: LCO2501154 | AL15: No | AM15: 1 | AQ15: =_xlfn.CONCAT(C15,"/",D15) -> 798/0 | AR15: =IF(D15=0,"DA CONTRATTO","SPOT") -> DA CONTRATTO | AS15: =IF(AD15=5,"P","C") -> P | AT15: =VLOOKUP(S15,'FILE PALLETTIZZAZIONI DB SRL'!B:H,5,FALSE) -> #N/A | AU15: =TEXT(N15,"gggg") -> venerdì | AV15: =WEEKNUM(N15) -> 49 | AW15: =IF(AND(ISBLANK(N15),AS15="P"), "ATTENZIONE: Data produzione non pianificata", IF(AND(ISBLANK(N15),AS15="C"), "ATTENZIONE: Data arrivo merce acquisti non presente", IF(O15-N15>=AP15, "Data sped. utile INSERITA", "ATTENZIONE: GG. resa non adeguati"))) -> Data sped. utile INSERITA | AX15: =IF(ISBLANK(O15), "ATTENZIONE: Data non inserita", IF(O15<=param!B2, "ATTENZIONE: Ritardo, Avvertire il cliente", "Data cons. rich. INSERITA")) -> Data cons. rich. INSERITA | AY15: =IF(OR(ISBLANK(AP15),ISBLANK(AH15)), "ATTENZIONE: Vettore non associato", IF(V15="VETTORE", "Tipo spedizione: VETTORE", IF(V15="DESTINATARIO", "Tipo spedizione: DESTINATARIO", IF(ISBLANK(V15), "ATTENZIONE: Vettore vuoto", "?")))) -> ATTENZIONE: Vettore non associato | AZ15: =IF(AM15=1, "Città OK", "ATTENZIONE: CAP non presente") -> Città OK | BA15: ATTENZIONE: Giorno congruo presa vettore | BB15: =_xlfn.CONCAT(AW15," - ",AX15," - ",AY15," - ",AZ15," - ","Data: ",BA15) -> Data sped. utile INSERITA - Data cons. rich. INSERITA - ATTENZIONE: Vettore non associato - Città OK - Data: ATTENZIONE: Giorno congruo presa vettore
A16: S | B16: 15 | C16: 799 | D16: 0 | E16: 45972 | F16: 284 | G16: LA SUISSA S.R.L. | H16: MPGRMPT50625SAL/G21 | I16: AFR753010/G21 | J16: Granella di Mandorle Pel Tost Sal E Grande | K16: 640 | M16: 640 | O16: 46001 | P16: TRASPORTI RECUPERO SRL | Q16: 8 | R16: 10 | S16: G21 | T16: Non evaso | U16: DDP | V16: VETTORE | W16: LA SUISSA | X16: 15061 ARQUATA SCRIVIA | Y16: 4 | Z16: GRANELLE | AA16: 199 | AB16: MANDORLE PELATE TOSTATE | AC16: 120 | AD16: 4 | AE16: PRODOTTI COMMERCIALIZZATI | AF16: 1 | AG16: PRODOTTO FINITO | AH16: 70 | AJ16: LCO2501155 | AL16: No | AM16: 1 | AQ16: =_xlfn.CONCAT(C16,"/",D16) -> 799/0 | AR16: =IF(D16=0,"DA CONTRATTO","SPOT") -> DA CONTRATTO | AS16: =IF(AD16=5,"P","C") -> C | AT16: =VLOOKUP(S16,'FILE PALLETTIZZAZIONI DB SRL'!B:H,5,FALSE) -> 2 | AU16: =TEXT(N16,"gggg") -> sabato | AV16: =WEEKNUM(N16) -> 0 | AW16: =IF(AND(ISBLANK(N16),AS16="P"), "ATTENZIONE: Data produzione non pianificata", IF(AND(ISBLANK(N16),AS16="C"), "ATTENZIONE: Data arrivo merce acquisti non presente", IF(O16-N16>=AP16, "Data sped. utile INSERITA", "ATTENZIONE: GG. resa non adeguati"))) -> ATTENZIONE: Data arrivo merce acquisti non presente | AX16: =IF(ISBLANK(O16), "ATTENZIONE: Data non inserita", IF(O16<=param!B2, "ATTENZIONE: Ritardo, Avvertire il cliente", "Data cons. rich. INSERITA")) -> Data cons. rich. INSERITA | AY16: =IF(OR(ISBLANK(AP16),ISBLANK(AH16)), "ATTENZIONE: Vettore non associato", IF(V16="VETTORE", "Tipo spedizione: VETTORE", IF(V16="DESTINATARIO", "Tipo spedizione: DESTINATARIO", IF(ISBLANK(V16), "ATTENZIONE: Vettore vuoto", "?")))) -> ATTENZIONE: Vettore non associato | AZ16: =IF(AM16=1, "Città OK", "ATTENZIONE: CAP non presente") -> Città OK | BA16: ATTENZIONE: Giorno congruo presa vettore | BB16: =_xlfn.CONCAT(AW16," - ",AX16," - ",AY16," - ",AZ16," - ","Data: ",BA16) -> ATTENZIONE: Data arrivo merce acquisti non presente - Data cons. rich. INSERITA - ATTENZIONE: Vettore non associato - Città OK - Data: ATTENZIONE: Giorno congruo presa vettore
A17: S | B17: 16 | C17: 799 | D17: 0 | E17: 45972 | F17: 284 | G17: LA SUISSA S.R.L. | H17: MPGRMPT50625SAL/B500 | I17: AFR753010/B500 | J17: Granella di Mandorle Pel Tost Sal E Grande | K17: 0.5 | M17: 0.5 | O17: 46001 | P17: TRASPORTI RECUPERO SRL | Q17: 8 | R17: 10 | S17: BSV500 | T17: Non evaso | U17: DDP | V17: VETTORE | W17: LA SUISSA | X17: 15061 ARQUATA SCRIVIA | Y17: 4 | Z17: GRANELLE | AA17: 199 | AB17: MANDORLE PELATE TOSTATE | AC17: 120 | AD17: 4 | AE17: PRODOTTI COMMERCIALIZZATI | AF17: 1 | AG17: PRODOTTO FINITO | AH17: 70 | AJ17: LCO2501155 | AL17: No | AM17: 1 | AQ17: =_xlfn.CONCAT(C17,"/",D17) -> 799/0 | AR17: =IF(D17=0,"DA CONTRATTO","SPOT") -> DA CONTRATTO | AS17: =IF(AD17=5,"P","C") -> C | AT17: =VLOOKUP(S17,'FILE PALLETTIZZAZIONI DB SRL'!B:H,5,FALSE) -> #N/A | AU17: =TEXT(N17,"gggg") -> sabato | AV17: =WEEKNUM(N17) -> 0 | AW17: =IF(AND(ISBLANK(N17),AS17="P"), "ATTENZIONE: Data produzione non pianificata", IF(AND(ISBLANK(N17),AS17="C"), "ATTENZIONE: Data arrivo merce acquisti non presente", IF(O17-N17>=AP17, "Data sped. utile INSERITA", "ATTENZIONE: GG. resa non adeguati"))) -> ATTENZIONE: Data arrivo merce acquisti non presente | AX17: =IF(ISBLANK(O17), "ATTENZIONE: Data non inserita", IF(O17<=param!B2, "ATTENZIONE: Ritardo, Avvertire il cliente", "Data cons. rich. INSERITA")) -> Data cons. rich. INSERITA | AY17: =IF(OR(ISBLANK(AP17),ISBLANK(AH17)), "ATTENZIONE: Vettore non associato", IF(V17="VETTORE", "Tipo spedizione: VETTORE", IF(V17="DESTINATARIO", "Tipo spedizione: DESTINATARIO", IF(ISBLANK(V17), "ATTENZIONE: Vettore vuoto", "?")))) -> ATTENZIONE: Vettore non associato | AZ17: =IF(AM17=1, "Città OK", "ATTENZIONE: CAP non presente") -> Città OK | BA17: ATTENZIONE: Giorno congruo presa vettore | BB17: =_xlfn.CONCAT(AW17," - ",AX17," - ",AY17," - ",AZ17," - ","Data: ",BA17) -> ATTENZIONE: Data arrivo merce acquisti non presente - Data cons. rich. INSERITA - ATTENZIONE: Vettore non associato - Città OK - Data: ATTENZIONE: Giorno congruo presa vettore
A18: S | B18: 17 | C18: 800 | D18: 0 | E18: 45972 | F18: 284 | G18: LA SUISSA S.R.L. | H18: GRPST51225SAL/G21 | I18: AFR753011/G21 | J18: Granella di Pistacchi Sgusciati Tost Sal E Grande | K18: 640 | M18: 640 | N18: 45996 | O18: 46001 | P18: TRASPORTI RECUPERO SRL | Q18: 8 | R18: 10 | S18: G21 | T18: Non evaso | U18: DDP | V18: VETTORE | W18: LA SUISSA | X18: 15061 ARQUATA SCRIVIA | Y18: 5 | Z18: GRANELLE | AA18: 208 | AB18: PISTACCHI SGUSCIATI TOSTAT | AC18: 120 | AD18: 5 | AE18: PRODOTTI DI BARTOLO | AF18: 1 | AG18: PRODOTTO FINITO | AH18: 70 | AJ18: LCO2501156 | AL18: No | AM18: 1 | AQ18: =_xlfn.CONCAT(C18,"/",D18) -> 800/0 | AR18: =IF(D18=0,"DA CONTRATTO","SPOT") -> DA CONTRATTO | AS18: =IF(AD18=5,"P","C") -> P | AT18: =VLOOKUP(S18,'FILE PALLETTIZZAZIONI DB SRL'!B:H,5,FALSE) -> 2 | AU18: =TEXT(N18,"gggg") -> venerdì | AV18: =WEEKNUM(N18) -> 49 | AW18: =IF(AND(ISBLANK(N18),AS18="P"), "ATTENZIONE: Data produzione non pianificata", IF(AND(ISBLANK(N18),AS18="C"), "ATTENZIONE: Data arrivo merce acquisti non presente", IF(O18-N18>=AP18, "Data sped. utile INSERITA", "ATTENZIONE: GG. resa non adeguati"))) -> Data sped. utile INSERITA | AX18: =IF(ISBLANK(O18), "ATTENZIONE: Data non inserita", IF(O18<=param!B2, "ATTENZIONE: Ritardo, Avvertire il cliente", "Data cons. rich. INSERITA")) -> Data cons. rich. INSERITA | AY18: =IF(OR(ISBLANK(AP18),ISBLANK(AH18)), "ATTENZIONE: Vettore non associato", IF(V18="VETTORE", "Tipo spedizione: VETTORE", IF(V18="DESTINATARIO", "Tipo spedizione: DESTINATARIO", IF(ISBLANK(V18), "ATTENZIONE: Vettore vuoto", "?")))) -> ATTENZIONE: Vettore non associato | AZ18: =IF(AM18=1, "Città OK", "ATTENZIONE: CAP non presente") -> Città OK | BA18: ATTENZIONE: Giorno congruo presa vettore | BB18: =_xlfn.CONCAT(AW18," - ",AX18," - ",AY18," - ",AZ18," - ","Data: ",BA18) -> Data sped. utile INSERITA - Data cons. rich. INSERITA - ATTENZIONE: Vettore non associato - Città OK - Data: ATTENZIONE: Giorno congruo presa vettore
A19: S | B19: 18 | C19: 800 | D19: 0 | E19: 45972 | F19: 284 | G19: LA SUISSA S.R.L. | H19: GRPST51225SAL/BSV500 | I19: AFR753011/BSV500 | J19: Granella di Pistacchi Sgusciati Tost Sal E Grande | K19: 0.5 | M19: 0.5 | N19: 45996 | O19: 46001 | P19: TRASPORTI RECUPERO SRL | Q19: 8 | R19: 10 | S19: BSV500 | T19: Non evaso | U19: DDP | V19: VETTORE | W19: LA SUISSA | X19: 15061 ARQUATA SCRIVIA | Y19: 5 | Z19: GRANELLE | AA19: 208 | AB19: PISTACCHI SGUSCIATI TOSTAT | AC19: 120 | AD19: 5 | AE19: PRODOTTI DI BARTOLO | AF19: 1 | AG19: PRODOTTO FINITO | AH19: 70 | AJ19: LCO2501156 | AL19: No | AM19: 1 | AQ19: =_xlfn.CONCAT(C19,"/",D19) -> 800/0 | AR19: =IF(D19=0,"DA CONTRATTO","SPOT") -> DA CONTRATTO | AS19: =IF(AD19=5,"P","C") -> P | AT19: =VLOOKUP(S19,'FILE PALLETTIZZAZIONI DB SRL'!B:H,5,FALSE) -> #N/A | AU19: =TEXT(N19,"gggg") -> venerdì | AV19: =WEEKNUM(N19) -> 49 | AW19: =IF(AND(ISBLANK(N19),AS19="P"), "ATTENZIONE: Data produzione non pianificata", IF(AND(ISBLANK(N19),AS19="C"), "ATTENZIONE: Data arrivo merce acquisti non presente", IF(O19-N19>=AP19, "Data sped. utile INSERITA", "ATTENZIONE: GG. resa non adeguati"))) -> Data sped. utile INSERITA | AX19: =IF(ISBLANK(O19), "ATTENZIONE: Data non inserita", IF(O19<=param!B2, "ATTENZIONE: Ritardo, Avvertire il cliente", "Data cons. rich. INSERITA")) -> Data cons. rich. INSERITA | AY19: =IF(OR(ISBLANK(AP19),ISBLANK(AH19)), "ATTENZIONE: Vettore non associato", IF(V19="VETTORE", "Tipo spedizione: VETTORE", IF(V19="DESTINATARIO", "Tipo spedizione: DESTINATARIO", IF(ISBLANK(V19), "ATTENZIONE: Vettore vuoto", "?")))) -> ATTENZIONE: Vettore non associato | AZ19: =IF(AM19=1, "Città OK", "ATTENZIONE: CAP non presente") -> Città OK | BA19: ATTENZIONE: Giorno congruo presa vettore | BB19: =_xlfn.CONCAT(AW19," - ",AX19," - ",AY19," - ",AZ19," - ","Data: ",BA19) -> Data sped. utile INSERITA - Data cons. rich. INSERITA - ATTENZIONE: Vettore non associato - Città OK - Data: ATTENZIONE: Giorno congruo presa vettore
A20: S | B20: 19 | C20: 813 | D20: 0 | E20: 45975 | F20: 284 | G20: LA SUISSA S.R.L. | H20: MPGRMPT50825SAL/G21 | I20: AFR753110/G21 | J20: Granella di Mandorle Pel. Tostate Salate IT Grande | K20: 640 | M20: 640 | O20: 46009 | P20: CURRO' TRASPORTI SRL | Q20: 8 | R20: 10 | S20: G21 | T20: Non evaso | U20: DDP | V20: VETTORE | W20: LA SUISSA | X20: 15061 ARQUATA SCRIVIA | Y20: 4 | Z20: GRANELLE | AA20: 199 | AB20: MANDORLE PELATE TOSTATE | AC20: 120 | AD20: 4 | AE20: PRODOTTI COMMERCIALIZZATI | AF20: 1 | AG20: PRODOTTO FINITO | AH20: 2 | AJ20: LCO2501172 | AL20: No | AM20: 1 | AQ20: =_xlfn.CONCAT(C20,"/",D20) -> 813/0 | AR20: =IF(D20=0,"DA CONTRATTO","SPOT") -> DA CONTRATTO | AS20: =IF(AD20=5,"P","C") -> C | AT20: =VLOOKUP(S20,'FILE PALLETTIZZAZIONI DB SRL'!B:H,5,FALSE) -> 2 | AU20: =TEXT(N20,"gggg") -> sabato | AV20: =WEEKNUM(N20) -> 0 | AW20: =IF(AND(ISBLANK(N20),AS20="P"), "ATTENZIONE: Data produzione non pianificata", IF(AND(ISBLANK(N20),AS20="C"), "ATTENZIONE: Data arrivo merce acquisti non presente", IF(O20-N20>=AP20, "Data sped. utile INSERITA", "ATTENZIONE: GG. resa non adeguati"))) -> ATTENZIONE: Data arrivo merce acquisti non presente | AX20: =IF(ISBLANK(O20), "ATTENZIONE: Data non inserita", IF(O20<=param!B2, "ATTENZIONE: Ritardo, Avvertire il cliente", "Data cons. rich. INSERITA")) -> Data cons. rich. INSERITA | AY20: =IF(OR(ISBLANK(AP20),ISBLANK(AH20)), "ATTENZIONE: Vettore non associato", IF(V20="VETTORE", "Tipo spedizione: VETTORE", IF(V20="DESTINATARIO", "Tipo spedizione: DESTINATARIO", IF(ISBLANK(V20), "ATTENZIONE: Vettore vuoto", "?")))) -> ATTENZIONE: Vettore non associato | AZ20: =IF(AM20=1, "Città OK", "ATTENZIONE: CAP non presente") -> Città OK | BA20: ATTENZIONE: Giorno congruo presa vettore | BB20: =_xlfn.CONCAT(AW20," - ",AX20," - ",AY20," - ",AZ20," - ","Data: ",BA20) -> ATTENZIONE: Data arrivo merce acquisti non presente - Data cons. rich. INSERITA - ATTENZIONE: Vettore non associato - Città OK - Data: ATTENZIONE: Giorno congruo presa vettore
A21: S | B21: 20 | C21: 813 | D21: 0 | E21: 45975 | F21: 284 | G21: LA SUISSA S.R.L. | H21: MPGRMPT50825SAL/B500 | I21: AFR753110/BSV500 | J21: Granella di Mandorle Pel. Tostate Salate IT Grande | K21: 0.5 | M21: 0.5 | O21: 46009 | P21: CURRO' TRASPORTI SRL | Q21: 8 | R21: 10 | S21: BSV500 | T21: Non evaso | U21: DDP | V21: VETTORE | W21: LA SUISSA | X21: 15061 ARQUATA SCRIVIA | Y21: 4 | Z21: GRANELLE | AA21: 199 | AB21: MANDORLE PELATE TOSTATE | AC21: 120 | AD21: 4 | AE21: PRODOTTI COMMERCIALIZZATI | AF21: 1 | AG21: PRODOTTO FINITO | AH21: 2 | AJ21: LCO2501172 | AL21: No | AM21: 1 | AQ21: =_xlfn.CONCAT(C21,"/",D21) -> 813/0 | AR21: =IF(D21=0,"DA CONTRATTO","SPOT") -> DA CONTRATTO | AS21: =IF(AD21=5,"P","C") -> C | AT21: =VLOOKUP(S21,'FILE PALLETTIZZAZIONI DB SRL'!B:H,5,FALSE) -> #N/A | AU21: =TEXT(N21,"gggg") -> sabato | AV21: =WEEKNUM(N21) -> 0 | AW21: =IF(AND(ISBLANK(N21),AS21="P"), "ATTENZIONE: Data produzione non pianificata", IF(AND(ISBLANK(N21),AS21="C"), "ATTENZIONE: Data arrivo merce acquisti non presente", IF(O21-N21>=AP21, "Data sped. utile INSERITA", "ATTENZIONE: GG. resa non adeguati"))) -> ATTENZIONE: Data arrivo merce acquisti non presente | AX21: =IF(ISBLANK(O21), "ATTENZIONE: Data non inserita", IF(O21<=param!B2, "ATTENZIONE: Ritardo, Avvertire il cliente", "Data cons. rich. INSERITA")) -> Data cons. rich. INSERITA | AY21: =IF(OR(ISBLANK(AP21),ISBLANK(AH21)), "ATTENZIONE: Vettore non associato", IF(V21="VETTORE", "Tipo spedizione: VETTORE", IF(V21="DESTINATARIO", "Tipo spedizione: DESTINATARIO", IF(ISBLANK(V21), "ATTENZIONE: Vettore vuoto", "?")))) -> ATTENZIONE: Vettore non associato | AZ21: =IF(AM21=1, "Città OK", "ATTENZIONE: CAP non presente") -> Città OK | BA21: ATTENZIONE: Giorno congruo presa vettore | BB21: =_xlfn.CONCAT(AW21," - ",AX21," - ",AY21," - ",AZ21," - ","Data: ",BA21) -> ATTENZIONE: Data arrivo merce acquisti non presente - Data cons. rich. INSERITA - ATTENZIONE: Vettore non associato - Città OK - Data: ATTENZIONE: Giorno congruo presa vettore
A22: S | B22: 21 | C22: 814 | D22: 0 | E22: 45975 | F22: 284 | G22: LA SUISSA S.R.L. | H22: GRPSTS51125SAL/G21 | I22: AFR753111/G21 | J22: Granella di Pistacchi Sg. Tostati Salati IT Grande | K22: 640 | M22: 640 | O22: 46009 | P22: CURRO' TRASPORTI SRL | Q22: 8 | R22: 10 | S22: G21 | T22: Non evaso | U22: DDP | V22: VETTORE | W22: LA SUISSA | X22: 15061 ARQUATA SCRIVIA | Y22: 5 | Z22: GRANELLE | AA22: 208 | AB22: PISTACCHI SGUSCIATI TOSTAT | AC22: 120 | AD22: 5 | AE22: PRODOTTI DI BARTOLO | AF22: 1 | AG22: PRODOTTO FINITO | AH22: 2 | AJ22: LCO2501173 | AL22: No | AM22: 1 | AQ22: =_xlfn.CONCAT(C22,"/",D22) -> 814/0 | AR22: =IF(D22=0,"DA CONTRATTO","SPOT") -> DA CONTRATTO | AS22: =IF(AD22=5,"P","C") -> P | AT22: =VLOOKUP(S22,'FILE PALLETTIZZAZIONI DB SRL'!B:H,5,FALSE) -> 2 | AU22: =TEXT(N22,"gggg") -> sabato | AV22: =WEEKNUM(N22) -> 0 | AW22: =IF(AND(ISBLANK(N22),AS22="P"), "ATTENZIONE: Data produzione non pianificata", IF(AND(ISBLANK(N22),AS22="C"), "ATTENZIONE: Data arrivo merce acquisti non presente", IF(O22-N22>=AP22, "Data sped. utile INSERITA", "ATTENZIONE: GG. resa non adeguati"))) -> ATTENZIONE: Data produzione non pianificata | AX22: =IF(ISBLANK(O22), "ATTENZIONE: Data non inserita", IF(O22<=param!B2, "ATTENZIONE: Ritardo, Avvertire il cliente", "Data cons. rich. INSERITA")) -> Data cons. rich. INSERITA | AY22: =IF(OR(ISBLANK(AP22),ISBLANK(AH22)), "ATTENZIONE: Vettore non associato", IF(V22="VETTORE", "Tipo spedizione: VETTORE", IF(V22="DESTINATARIO", "Tipo spedizione: DESTINATARIO", IF(ISBLANK(V22), "ATTENZIONE: Vettore vuoto", "?")))) -> ATTENZIONE: Vettore non associato | AZ22: =IF(AM22=1, "Città OK", "ATTENZIONE: CAP non presente") -> Città OK | BA22: ATTENZIONE: Giorno congruo presa vettore | BB22: =_xlfn.CONCAT(AW22," - ",AX22," - ",AY22," - ",AZ22," - ","Data: ",BA22) -> ATTENZIONE: Data produzione non pianificata - Data cons. rich. INSERITA - ATTENZIONE: Vettore non associato - Città OK - Data: ATTENZIONE: Giorno congruo presa vettore
A23: S | B23: 22 | C23: 814 | D23: 0 | E23: 45975 | F23: 284 | G23: LA SUISSA S.R.L. | H23: GRPSTS51125SAL/B500 | I23: AFR753111/B500 | J23: Granella di Pistacchi Sg. Tostati Salati IT Grande | K23: 0.5 | M23: 0.5 | O23: 46009 | P23: CURRO' TRASPORTI SRL | Q23: 8 | R23: 10 | S23: BSV500 | T23: Non evaso | U23: DDP | V23: VETTORE | W23: LA SUISSA | X23: 15061 ARQUATA SCRIVIA | Y23: 5 | Z23: GRANELLE | AA23: 208 | AB23: PISTACCHI SGUSCIATI TOSTAT | AC23: 120 | AD23: 5 | AE23: PRODOTTI DI BARTOLO | AF23: 1 | AG23: PRODOTTO FINITO | AH23: 2 | AJ23: LCO2501173 | AL23: No | AM23: 1 | AQ23: =_xlfn.CONCAT(C23,"/",D23) -> 814/0 | AR23: =IF(D23=0,"DA CONTRATTO","SPOT") -> DA CONTRATTO | AS23: =IF(AD23=5,"P","C") -> P | AT23: =VLOOKUP(S23,'FILE PALLETTIZZAZIONI DB SRL'!B:H,5,FALSE) -> #N/A | AU23: =TEXT(N23,"gggg") -> sabato | AV23: =WEEKNUM(N23) -> 0 | AW23: =IF(AND(ISBLANK(N23),AS23="P"), "ATTENZIONE: Data produzione non pianificata", IF(AND(ISBLANK(N23),AS23="C"), "ATTENZIONE: Data arrivo merce acquisti non presente", IF(O23-N23>=AP23, "Data sped. utile INSERITA", "ATTENZIONE: GG. resa non adeguati"))) -> ATTENZIONE: Data produzione non pianificata | AX23: =IF(ISBLANK(O23), "ATTENZIONE: Data non inserita", IF(O23<=param!B2, "ATTENZIONE: Ritardo, Avvertire il cliente", "Data cons. rich. INSERITA")) -> Data cons. rich. INSERITA | AY23: =IF(OR(ISBLANK(AP23),ISBLANK(AH23)), "ATTENZIONE: Vettore non associato", IF(V23="VETTORE", "Tipo spedizione: VETTORE", IF(V23="DESTINATARIO", "Tipo spedizione: DESTINATARIO", IF(ISBLANK(V23), "ATTENZIONE: Vettore vuoto", "?")))) -> ATTENZIONE: Vettore non associato | AZ23: =IF(AM23=1, "Città OK", "ATTENZIONE: CAP non presente") -> Città OK | BA23: ATTENZIONE: Giorno congruo presa vettore | BB23: =_xlfn.CONCAT(AW23," - ",AX23," - ",AY23," - ",AZ23," - ","Data: ",BA23) -> ATTENZIONE: Data produzione non pianificata - Data cons. rich. INSERITA - ATTENZIONE: Vettore non associato - Città OK - Data: ATTENZIONE: Giorno congruo presa vettore
A24: S | B24: 23 | C24: 776 | D24: 0 | E24: 45958 | F24: 343 | G24: ESKIGEL S.R.L. | H24: PP1012/P10 | I24: 11000084/P10 | J24: PASTA PISTACCHIO S 11000084 | K24: 1000 | M24: 1000 | O24: 46029 | P24: RUSTICO BRUNO | Q24: 8 | R24: 10 | S24: P10 | T24: Non evaso | U24: DDP | V24: VETTORE | W24: ESKIGEL S.R.L. | X24: 05100 TERNI TR | Y24: 5 | Z24: PASTE | AA24: 870 | AB24: PISTACCHIO | AC24: 235 | AD24: 5 | AE24: PRODOTTI DI BARTOLO | AF24: 1 | AG24: PRODOTTO FINITO | AH24: 1 | AJ24: 25005794 OP | AL24: No | AM24: 1 | AN24: martedì | AO24: venerdì | AP24: 5 | AQ24: =_xlfn.CONCAT(C24,"/",D24) -> 776/0 | AR24: =IF(D24=0,"DA CONTRATTO","SPOT") -> DA CONTRATTO | AS24: =IF(AD24=5,"P","C") -> P | AT24: =VLOOKUP(S24,'FILE PALLETTIZZAZIONI DB SRL'!B:H,5,FALSE) -> 25 | AU24: =TEXT(N24,"gggg") -> sabato | AV24: =WEEKNUM(N24) -> 0 | AW24: =IF(AND(ISBLANK(N24),AS24="P"), "ATTENZIONE: Data produzione non pianificata", IF(AND(ISBLANK(N24),AS24="C"), "ATTENZIONE: Data arrivo merce acquisti non presente", IF(O24-N24>=AP24, "Data sped. utile INSERITA", "ATTENZIONE: GG. resa non adeguati"))) -> ATTENZIONE: Data produzione non pianificata | AX24: =IF(ISBLANK(O24), "ATTENZIONE: Data non inserita", IF(O24<=param!B2, "ATTENZIONE: Ritardo, Avvertire il cliente", "Data cons. rich. INSERITA")) -> Data cons. rich. INSERITA | AY24: =IF(OR(ISBLANK(AP24),ISBLANK(AH24)), "ATTENZIONE: Vettore non associato", IF(V24="VETTORE", "Tipo spedizione: VETTORE", IF(V24="DESTINATARIO", "Tipo spedizione: DESTINATARIO", IF(ISBLANK(V24), "ATTENZIONE: Vettore vuoto", "?")))) -> Tipo spedizione: VETTORE | AZ24: =IF(AM24=1, "Città OK", "ATTENZIONE: CAP non presente") -> Città OK | BA24: ATTENZIONE: Giorno congruo presa vettore | BB24: =_xlfn.CONCAT(AW24," - ",AX24," - ",AY24," - ",AZ24," - ","Data: ",BA24) -> ATTENZIONE: Data produzione non pianificata - Data cons. rich. INSERITA - Tipo spedizione: VETTORE - Città OK - Data: ATTENZIONE: Giorno congruo presa vettore
A25: S | B25: 25 | C25: 777 | D25: 0 | E25: 45958 | F25: 343 | G25: ESKIGEL S.R.L. | H25: PPAPG2/P10 | I25: 11001335/P10 | J25: PASTA PISTACCHIO U 11001335 | K25: 1000 | M25: 1000 | O25: 46029 | P25: RUSTICO BRUNO | Q25: 8 | R25: 10 | S25: P10 | T25: Non evaso | U25: DDP | V25: VETTORE | W25: ESKIGEL S.R.L. | X25: 05100 TERNI TR | Y25: 5 | Z25: PASTE | AA25: 870 | AB25: PISTACCHIO | AC25: 235 | AD25: 5 | AE25: PRODOTTI DI BARTOLO | AF25: 1 | AG25: PRODOTTO FINITO | AH25: 1 | AJ25: 25005794 OP | AL25: No | AM25: 1 | AN25: martedì | AO25: venerdì | AP25: 5 | AQ25: =_xlfn.CONCAT(C25,"/",D25) -> 777/0 | AR25: =IF(D25=0,"DA CONTRATTO","SPOT") -> DA CONTRATTO | AS25: =IF(AD25=5,"P","C") -> P | AT25: =VLOOKUP(S25,'FILE PALLETTIZZAZIONI DB SRL'!B:H,5,FALSE) -> 25 | AU25: =TEXT(N25,"gggg") -> sabato | AV25: =WEEKNUM(N25) -> 0 | AW25: =IF(AND(ISBLANK(N25),AS25="P"), "ATTENZIONE: Data produzione non pianificata", IF(AND(ISBLANK(N25),AS25="C"), "ATTENZIONE: Data arrivo merce acquisti non presente", IF(O25-N25>=AP25, "Data sped. utile INSERITA", "ATTENZIONE: GG. resa non adeguati"))) -> ATTENZIONE: Data produzione non pianificata | AX25: =IF(ISBLANK(O25), "ATTENZIONE: Data non inserita", IF(O25<=param!B2, "ATTENZIONE: Ritardo, Avvertire il cliente", "Data cons. rich. INSERITA")) -> Data cons. rich. INSERITA | AY25: =IF(OR(ISBLANK(AP25),ISBLANK(AH25)), "ATTENZIONE: Vettore non associato", IF(V25="VETTORE", "Tipo spedizione: VETTORE", IF(V25="DESTINATARIO", "Tipo spedizione: DESTINATARIO", IF(ISBLANK(V25), "ATTENZIONE: Vettore vuoto", "?")))) -> Tipo spedizione: VETTORE | AZ25: =IF(AM25=1, "Città OK", "ATTENZIONE: CAP non presente") -> Città OK | BA25: ATTENZIONE: Giorno congruo presa vettore | BB25: =_xlfn.CONCAT(AW25," - ",AX25," - ",AY25," - ",AZ25," - ","Data: ",BA25) -> ATTENZIONE: Data produzione non pianificata - Data cons. rich. INSERITA - Tipo spedizione: VETTORE - Città OK - Data: ATTENZIONE: Giorno congruo presa vettore
A26: S | B26: 27 | C26: 778 | D26: 0 | E26: 45958 | F26: 343 | G26: ESKIGEL S.R.L. | H26: GRPST51125/G23 | I26: 14000105/G23 | J26: GRANELLA DI PISTACCHI TOSTATI S 14000105 CAL. 2/4 | K26: 640 | M26: 640 | O26: 46029 | P26: RUSTICO BRUNO | Q26: 8 | R26: 10 | S26: G23 | T26: Non evaso | U26: DDP | V26: VETTORE | W26: ESKIGEL S.R.L. | X26: 05100 TERNI TR | Y26: 5 | Z26: GRANELLE | AA26: 208 | AB26: PISTACCHI SGUSCIATI TOSTAT | AC26: 120 | AD26: 5 | AE26: PRODOTTI DI BARTOLO | AF26: 1 | AG26: PRODOTTO FINITO | AH26: 1 | AJ26: 25005794 OP | AL26: No | AM26: 1 | AN26: martedì | AO26: venerdì | AP26: 5 | AQ26: =_xlfn.CONCAT(C26,"/",D26) -> 778/0 | AR26: =IF(D26=0,"DA CONTRATTO","SPOT") -> DA CONTRATTO | AS26: =IF(AD26=5,"P","C") -> P | AT26: =VLOOKUP(S26,'FILE PALLETTIZZAZIONI DB SRL'!B:H,5,FALSE) -> 32 | AU26: =TEXT(N26,"gggg") -> sabato | AV26: =WEEKNUM(N26) -> 0 | AW26: =IF(AND(ISBLANK(N26),AS26="P"), "ATTENZIONE: Data produzione non pianificata", IF(AND(ISBLANK(N26),AS26="C"), "ATTENZIONE: Data arrivo merce acquisti non presente", IF(O26-N26>=AP26, "Data sped. utile INSERITA", "ATTENZIONE: GG. resa non adeguati"))) -> ATTENZIONE: Data produzione non pianificata | AX26: =IF(ISBLANK(O26), "ATTENZIONE: Data non inserita", IF(O26<=param!B2, "ATTENZIONE: Ritardo, Avvertire il cliente", "Data cons. rich. INSERITA")) -> Data cons. rich. INSERITA | AY26: =IF(OR(ISBLANK(AP26),ISBLANK(AH26)), "ATTENZIONE: Vettore non associato", IF(V26="VETTORE", "Tipo spedizione: VETTORE", IF(V26="DESTINATARIO", "Tipo spedizione: DESTINATARIO", IF(ISBLANK(V26), "ATTENZIONE: Vettore vuoto", "?")))) -> Tipo spedizione: VETTORE | AZ26: =IF(AM26=1, "Città OK", "ATTENZIONE: CAP non presente") -> Città OK | BA26: ATTENZIONE: Giorno congruo presa vettore | BB26: =_xlfn.CONCAT(AW26," - ",AX26," - ",AY26," - ",AZ26," - ","Data: ",BA26) -> ATTENZIONE: Data produzione non pianificata - Data cons. rich. INSERITA - Tipo spedizione: VETTORE - Città OK - Data: ATTENZIONE: Giorno congruo presa vettore
A27: S | B27: 29 | C27: 791 | D27: 0 | E27: 45967 | F27: 343 | G27: ESKIGEL S.R.L. | H27: PTRN5953/P10 | I27: 11000062/ P10 | J27: PASTA TORRONCINO SOLUBILE OE | K27: 500 | M27: 500 | O27: 46029 | P27: RUSTICO BRUNO | Q27: 8 | R27: 10 | S27: P10 | T27: Non evaso | U27: DDP | V27: VETTORE | W27: ESKIGEL S.R.L. | X27: 05100 TERNI TR | Y27: 5 | Z27: PASTE | AA27: 873 | AB27: TORRONCINO | AC27: 235 | AD27: 5 | AE27: PRODOTTI DI BARTOLO | AF27: 4 | AG27: SEMILAVORATO | AH27: 1 | AJ27: 25005794 OP | AL27: No | AM27: 1 | AN27: martedì | AO27: venerdì | AP27: 5 | AQ27: =_xlfn.CONCAT(C27,"/",D27) -> 791/0 | AR27: =IF(D27=0,"DA CONTRATTO","SPOT") -> DA CONTRATTO | AS27: =IF(AD27=5,"P","C") -> P | AT27: =VLOOKUP(S27,'FILE PALLETTIZZAZIONI DB SRL'!B:H,5,FALSE) -> 25 | AU27: =TEXT(N27,"gggg") -> sabato | AV27: =WEEKNUM(N27) -> 0 | AW27: =IF(AND(ISBLANK(N27),AS27="P"), "ATTENZIONE: Data produzione non pianificata", IF(AND(ISBLANK(N27),AS27="C"), "ATTENZIONE: Data arrivo merce acquisti non presente", IF(O27-N27>=AP27, "Data sped. utile INSERITA", "ATTENZIONE: GG. resa non adeguati"))) -> ATTENZIONE: Data produzione non pianificata | AX27: =IF(ISBLANK(O27), "ATTENZIONE: Data non inserita", IF(O27<=param!B2, "ATTENZIONE: Ritardo, Avvertire il cliente", "Data cons. rich. INSERITA")) -> Data cons. rich. INSERITA | AY27: =IF(OR(ISBLANK(AP27),ISBLANK(AH27)), "ATTENZIONE: Vettore non associato", IF(V27="VETTORE", "Tipo spedizione: VETTORE", IF(V27="DESTINATARIO", "Tipo spedizione: DESTINATARIO", IF(ISBLANK(V27), "ATTENZIONE: Vettore vuoto", "?")))) -> Tipo spedizione: VETTORE | AZ27: =IF(AM27=1, "Città OK", "ATTENZIONE: CAP non presente") -> Città OK | BA27: ATTENZIONE: Giorno congruo presa vettore | BB27: =_xlfn.CONCAT(AW27," - ",AX27," - ",AY27," - ",AZ27," - ","Data: ",BA27) -> ATTENZIONE: Data produzione non pianificata - Data cons. rich. INSERITA - Tipo spedizione: VETTORE - Città OK - Data: ATTENZIONE: Giorno congruo presa vettore
A28: S | B28: 31 | C28: 792 | D28: 0 | E28: 45967 | F28: 343 | G28: ESKIGEL S.R.L. | H28: COPP10-1/P10 | I28: 14003850/P10 | J28: SALSA ANIDRA PISTACCHIO | K28: 1000 | M28: 1000 | O28: 46029 | P28: RUSTICO BRUNO | S28: P10 | T28: Non evaso | U28: DDP | V28: VETTORE | W28: ESKIGEL S.R.L. | X28: 05100 TERNI TR | Y28: 5 | Z28: VARIEGATI | AA28: 870 | AB28: PISTACCHIO | AC28: 4 | AD28: 5 | AE28: PRODOTTI DI BARTOLO | AF28: 4 | AG28: SEMILAVORATO | AH28: 1 | AJ28: 25005794 OP | AL28: No | AM28: 1 | AN28: martedì | AO28: venerdì | AP28: 5 | AQ28: =_xlfn.CONCAT(C28,"/",D28) -> 792/0 | AR28: =IF(D28=0,"DA CONTRATTO","SPOT") -> DA CONTRATTO | AS28: =IF(AD28=5,"P","C") -> P | AT28: =VLOOKUP(S28,'FILE PALLETTIZZAZIONI DB SRL'!B:H,5,FALSE) -> 25 | AU28: =TEXT(N28,"gggg") -> sabato | AV28: =WEEKNUM(N28) -> 0 | AW28: =IF(AND(ISBLANK(N28),AS28="P"), "ATTENZIONE: Data produzione non pianificata", IF(AND(ISBLANK(N28),AS28="C"), "ATTENZIONE: Data arrivo merce acquisti non presente", IF(O28-N28>=AP28, "Data sped. utile INSERITA", "ATTENZIONE: GG. resa non adeguati"))) -> ATTENZIONE: Data produzione non pianificata | AX28: =IF(ISBLANK(O28), "ATTENZIONE: Data non inserita", IF(O28<=param!B2, "ATTENZIONE: Ritardo, Avvertire il cliente", "Data cons. rich. INSERITA")) -> Data cons. rich. INSERITA | AY28: =IF(OR(ISBLANK(AP28),ISBLANK(AH28)), "ATTENZIONE: Vettore non associato", IF(V28="VETTORE", "Tipo spedizione: VETTORE", IF(V28="DESTINATARIO", "Tipo spedizione: DESTINATARIO", IF(ISBLANK(V28), "ATTENZIONE: Vettore vuoto", "?")))) -> Tipo spedizione: VETTORE | AZ28: =IF(AM28=1, "Città OK", "ATTENZIONE: CAP non presente") -> Città OK | BA28: ATTENZIONE: Giorno congruo presa vettore | BB28: =_xlfn.CONCAT(AW28," - ",AX28," - ",AY28," - ",AZ28," - ","Data: ",BA28) -> ATTENZIONE: Data produzione non pianificata - Data cons. rich. INSERITA - Tipo spedizione: VETTORE - Città OK - Data: ATTENZIONE: Giorno congruo presa vettore
A29: S | B29: 37 | C29: 731 | D29: 0 | E29: 45925 | F29: 363 | G29: SAMMONTANA SPA Società Benefit | H29: COPG702/IBC1000 | I29: MPCC245/IBC1000 | J29: VARIEGATO CACAO NOCCIOLE NO LATTE GIRASOLE | K29: 10000 | M29: 10000 | O29: 46001 | P29: RUSTICO BRUNO | Q29: 8 | R29: 10 | S29: IBC100 | T29: Non evaso | U29: DDP | V29: VETTORE | W29: SAMMONTANA SPA | X29: 37030 VERONA | Y29: 5 | Z29: VARIEGATI | AA29: 550 | AB29: GIANDUIA | AC29: 4 | AD29: 5 | AE29: PRODOTTI DI BARTOLO | AF29: 1 | AG29: PRODOTTO FINITO | AH29: 1 | AJ29: 25OF022681-1 | AL29: No | AM29: 1 | AN29: martedì | AO29: venerdì | AP29: 5 | AQ29: =_xlfn.CONCAT(C29,"/",D29) -> 731/0 | AR29: =IF(D29=0,"DA CONTRATTO","SPOT") -> DA CONTRATTO | AS29: =IF(AD29=5,"P","C") -> P | AT29: =VLOOKUP(S29,'FILE PALLETTIZZAZIONI DB SRL'!B:H,5,FALSE) -> 1 | AU29: =TEXT(N29,"gggg") -> sabato | AV29: =WEEKNUM(N29) -> 0 | AW29: =IF(AND(ISBLANK(N29),AS29="P"), "ATTENZIONE: Data produzione non pianificata", IF(AND(ISBLANK(N29),AS29="C"), "ATTENZIONE: Data arrivo merce acquisti non presente", IF(O29-N29>=AP29, "Data sped. utile INSERITA", "ATTENZIONE: GG. resa non adeguati"))) -> ATTENZIONE: Data produzione non pianificata | AX29: =IF(ISBLANK(O29), "ATTENZIONE: Data non inserita", IF(O29<=param!B2, "ATTENZIONE: Ritardo, Avvertire il cliente", "Data cons. rich. INSERITA")) -> Data cons. rich. INSERITA | AY29: =IF(OR(ISBLANK(AP29),ISBLANK(AH29)), "ATTENZIONE: Vettore non associato", IF(V29="VETTORE", "Tipo spedizione: VETTORE", IF(V29="DESTINATARIO", "Tipo spedizione: DESTINATARIO", IF(ISBLANK(V29), "ATTENZIONE: Vettore vuoto", "?")))) -> Tipo spedizione: VETTORE | AZ29: =IF(AM29=1, "Città OK", "ATTENZIONE: CAP non presente") -> Città OK | BA29: ATTENZIONE: Giorno congruo presa vettore | BB29: =_xlfn.CONCAT(AW29," - ",AX29," - ",AY29," - ",AZ29," - ","Data: ",BA29) -> ATTENZIONE: Data produzione non pianificata - Data cons. rich. INSERITA - Tipo spedizione: VETTORE - Città OK - Data: ATTENZIONE: Giorno congruo presa vettore
A30: S | B30: 38 | C30: 732 | D30: 0 | E30: 45925 | F30: 363 | G30: SAMMONTANA SPA Società Benefit | H30: COPG702/IBC1000 | I30: MPCC245/IBC1000 | J30: VARIEGATO CACAO NOCCIOLE NO LATTE GIRASOLE | K30: 20000 | M30: 20000 | O30: 46009 | P30: RUSTICO BRUNO | Q30: 8 | R30: 10 | S30: IBC100 | T30: Non evaso | U30: DDP | V30: VETTORE | W30: SAMMONTANA SPA | X30: 37030 VERONA | Y30: 5 | Z30: VARIEGATI | AA30: 550 | AB30: GIANDUIA | AC30: 4 | AD30: 5 | AE30: PRODOTTI DI BARTOLO | AF30: 1 | AG30: PRODOTTO FINITO | AH30: 1 | AJ30: 25OF022681-1 | AL30: No | AM30: 1 | AN30: martedì | AO30: venerdì | AP30: 5 | AQ30: =_xlfn.CONCAT(C30,"/",D30) -> 732/0 | AR30: =IF(D30=0,"DA CONTRATTO","SPOT") -> DA CONTRATTO | AS30: =IF(AD30=5,"P","C") -> P | AT30: =VLOOKUP(S30,'FILE PALLETTIZZAZIONI DB SRL'!B:H,5,FALSE) -> 1 | AU30: =TEXT(N30,"gggg") -> sabato | AV30: =WEEKNUM(N30) -> 0 | AW30: =IF(AND(ISBLANK(N30),AS30="P"), "ATTENZIONE: Data produzione non pianificata", IF(AND(ISBLANK(N30),AS30="C"), "ATTENZIONE: Data arrivo merce acquisti non presente", IF(O30-N30>=AP30, "Data sped. utile INSERITA", "ATTENZIONE: GG. resa non adeguati"))) -> ATTENZIONE: Data produzione non pianificata | AX30: =IF(ISBLANK(O30), "ATTENZIONE: Data non inserita", IF(O30<=param!B2, "ATTENZIONE: Ritardo, Avvertire il cliente", "Data cons. rich. INSERITA")) -> Data cons. rich. INSERITA | AY30: =IF(OR(ISBLANK(AP30),ISBLANK(AH30)), "ATTENZIONE: Vettore non associato", IF(V30="VETTORE", "Tipo spedizione: VETTORE", IF(V30="DESTINATARIO", "Tipo spedizione: DESTINATARIO", IF(ISBLANK(V30), "ATTENZIONE: Vettore vuoto", "?")))) -> Tipo spedizione: VETTORE | AZ30: =IF(AM30=1, "Città OK", "ATTENZIONE: CAP non presente") -> Città OK | BA30: ATTENZIONE: Giorno congruo presa vettore | BB30: =_xlfn.CONCAT(AW30," - ",AX30," - ",AY30," - ",AZ30," - ","Data: ",BA30) -> ATTENZIONE: Data produzione non pianificata - Data cons. rich. INSERITA - Tipo spedizione: VETTORE - Città OK - Data: ATTENZIONE: Giorno congruo presa vettore
